Workbook

Sheet Özet
A1: RV32IMACBFV — Proje TODO ve İlerleme
A3: Genel Özet
A4: Toplam görev | B4: =COUNTA(Görevler!$A$2:$A$116) -> 115
A5: Tamamlandı | B5: =COUNTIF(Görevler!$H$2:$H$116,"Tamamlandı") -> 13
A6: Devam Ediyor | B6: =COUNTIF(Görevler!$H$2:$H$116,"Devam Ediyor") -> 3
A7: Yapılacak | B7: =COUNTIF(Görevler!$H$2:$H$116,"Yapılacak") -> 99
A8: Bloke | B8: =COUNTIF(Görevler!$H$2:$H$116,"Bloke") -> 0
A9: İlerleme % | B9: =IFERROR(B5/B4,0) -> 0.11304348
A11: Faz Bazında İlerleme
A12: Faz | B12: Toplam | C12: Tamamlandı | D12: İlerleme %
A13: Faz 0 | B13: =COUNTIF(Görevler!$B$2:$B$116,$A13) -> 12 | C13: =COUNTIFS(Görevler!$B$2:$B$116,$A13,Görevler!$H$2:$H$116,"Tamamlandı") -> 6 | D13: =IFERROR(C13/B13,0) -> 0.5
A14: Faz 1 | B14: =COUNTIF(Görevler!$B$2:$B$116,$A14) -> 26 | C14: =COUNTIFS(Görevler!$B$2:$B$116,$A14,Görevler!$H$2:$H$116,"Tamamlandı") -> 6 | D14: =IFERROR(C14/B14,0) -> 0.23076923
A15: Faz 2 | B15: =COUNTIF(Görevler!$B$2:$B$116,$A15) -> 7 | C15: =COUNTIFS(Görevler!$B$2:$B$116,$A15,Görevler!$H$2:$H$116,"Tamamlandı") -> 0 | D15: =IFERROR(C15/B15,0) -> 0
A16: Faz 3 | B16: =COUNTIF(Görevler!$B$2:$B$116,$A16) -> 15 | C16: =COUNTIFS(Görevler!$B$2:$B$116,$A16,Görevler!$H$2:$H$116,"Tamamlandı") -> 1 | D16: =IFERROR(C16/B16,0) -> 0.066666667
A17: Faz 4 | B17: =COUNTIF(Görevler!$B$2:$B$116,$A17) -> 5 | C17: =COUNTIFS(Görevler!$B$2:$B$116,$A17,Görevler!$H$2:$H$116,"Tamamlandı") -> 0 | D17: =IFERROR(C17/B17,0) -> 0
A18: Faz 5 | B18: =COUNTIF(Görevler!$B$2:$B$116,$A18) -> 10 | C18: =COUNTIFS(Görevler!$B$2:$B$116,$A18,Görevler!$H$2:$H$116,"Tamamlandı") -> 0 | D18: =IFERROR(C18/B18,0) -> 0
A19: Faz 6 | B19: =COUNTIF(Görevler!$B$2:$B$116,$A19) -> 9 | C19: =COUNTIFS(Görevler!$B$2:$B$116,$A19,Görevler!$H$2:$H$116,"Tamamlandı") -> 0 | D19: =IFERROR(C19/B19,0) -> 0
A20: Faz 7 | B20: =COUNTIF(Görevler!$B$2:$B$116,$A20) -> 5 | C20: =COUNTIFS(Görevler!$B$2:$B$116,$A20,Görevler!$H$2:$H$116,"Tamamlandı") -> 0 | D20: =IFERROR(C20/B20,0) -> 0
A21: Faz 8 | B21: =COUNTIF(Görevler!$B$2:$B$116,$A21) -> 5 | C21: =COUNTIFS(Görevler!$B$2:$B$116,$A21,Görevler!$H$2:$H$116,"Tamamlandı") -> 0 | D21: =IFERROR(C21/B21,0) -> 0
A22: Faz 9 | B22: =COUNTIF(Görevler!$B$2:$B$116,$A22) -> 3 | C22: =COUNTIFS(Görevler!$B$2:$B$116,$A22,Görevler!$H$2:$H$116,"Tamamlandı") -> 0 | D22: =IFERROR(C22/B22,0) -> 0
A23: Track-F | B23: =COUNTIF(Görevler!$B$2:$B$116,$A23) -> 11 | C23: =COUNTIFS(Görevler!$B$2:$B$116,$A23,Görevler!$H$2:$H$116,"Tamamlandı") -> 0 | D23: =IFERROR(C23/B23,0) -> 0
A24: Track-P | B24: =COUNTIF(Görevler!$B$2:$B$116,$A24) -> 4 | C24: =COUNTIFS(Görevler!$B$2:$B$116,$A24,Görevler!$H$2:$H$116,"Tamamlandı") -> 0 | D24: =IFERROR(C24/B24,0) -> 0
A25: İleri Mimari | B25: =COUNTIF(Görevler!$B$2:$B$116,$A25) -> 3 | C25: =COUNTIFS(Görevler!$B$2:$B$116,$A25,Görevler!$H$2:$H$116,"Tamamlandı") -> 0 | D25: =IFERROR(C25/B25,0) -> 0
A28: Lejant ve Kullanım
A29: • Durum: Yapılacak → Devam Ediyor → Tamamlandı (Bloke = engellenmiş)
A30: • Öncelik: Kritik > Yüksek > Orta > Düşük > Opsiyonel
A31: • Efor: S (küçük) · M (orta) · L (büyük) · XL (devasa)
A32: • Düzenlenecek sütunlar: Durum (H), Öncelik (G), Efor (F), Not (J). Diğerlerini değiştirme.
A33: • Görevler sekmesinde Durum/Öncelik/Efor hücrelerinde açılır menü var; renkler otomatik güncellenir.
A34: • Bu özet sayfası formüllüdür: Görevler'de durum değiştikçe sayılar ve yüzdeler kendiliğinden güncellenir.

Sheet Görevler
A1: ID | B1: Faz | C1: Kategori | D1: Görev | E1: Açıklama / Çıktı | F1: Efor | G1: Öncelik | H1: Durum | I1: Bağımlılık | J1: Not
A2: T001 | B2: Faz 0 | C2: Altyapı | D2: HDL seçimi: SystemVerilog | E2: ASIC araç desteği + paket/interface kolaylığı | F2: S | G2: Kritik | H2: Tamamlandı | I2: - | J2: Karar verildi
A3: T002 | B3: Faz 0 | C3: Altyapı | D3: Başlangıç mikromimari kararı (M0→M2) | E3: Önce single-cycle, sonra 5-stage | F3: S | G3: Kritik | H3: Tamamlandı | I3: - | J3: Karar verildi
A4: T003 | B4: Faz 0 | C4: Altyapı | D4: Repo / dizin yapısı | E4: rtl/tb/verif/syn/sw/flist… | F4: S | G4: Kritik | H4: Tamamlandı | I4: - | J4: Yerel olarak kuruldu
A5: T004 | B5: Faz 0 | C5: Tasarım | D5: riscv_pkg.sv (opcode/funct/enum) | E5: Ortak ISA sözlüğü | F5: S | G5: Kritik | H5: Devam Ediyor | I5: T003 | J5: İskeleti hazır, tamamlanacak
A6: T005 | B6: Faz 0 | C6: Tasarım | D6: core_config_pkg.sv (feature toggles) | E6: M_EN/F_EN/V_EN, XLEN, reset addr | F6: S | G6: Kritik | H6: Devam Ediyor | I6: T003 | J6: İskeleti hazır
A7: T006 | B7: Faz 0 | C7: Altyapı | D7: RISC-V GCC/LLVM toolchain | E7: Test programı derleme | F7: S | G7: Kritik | H7: Tamamlandı | I7: -
A8: T007 | B8: Faz 0 | C8: Altyapı | D8: Verilator kurulumu | E8: Hızlı simülasyon | F8: S | G8: Kritik | H8: Tamamlandı | I8: -
A9: T008 | B9: Faz 0 | C9: Altyapı | D9: Spike (golden model) kurulumu | E9: Referans ISA simülatörü | F9: S | G9: Kritik | H9: Tamamlandı | I9: -
A10: T009 | B10: Faz 0 | C10: Doğrulama | D10: Spike lockstep co-sim harness | E10: RTL↔Spike durum karşılaştırma | F10: M | G10: Kritik | H10: Yapılacak | I10: T007,T008 | J10: Doğrulamanın bel kemiği
A11: T010 | B11: Faz 0 | C11: Altyapı | D11: Lint (Verible/Verilator) | E11: Sentez öncesi hata yakalama | F11: S | G11: Yüksek | H11: Yapılacak | I11: -
A12: T011 | B12: Faz 0 | C12: Altyapı | D12: Formal (SymbiYosys) kurulumu | E12: Property tabanlı doğrulama | F12: S | G12: Orta | H12: Yapılacak | I12: -
A13: T012 | B13: Faz 0 | C13: Altyapı | D13: CI pipeline | E13: commit: lint+unit+smoke; nightly: full | F13: M | G13: Yüksek | H13: Yapılacak | I13: T007,T008,T010
A14: T013 | B14: Faz 1 | C14: Tasarım | D14: PC + PC-adder | E14: Sonraki komut adresi | F14: S | G14: Kritik | H14: Tamamlandı | I14: T004 | J14: M0 single-cycle
A15: T014 | B15: Faz 1 | C15: Tasarım | D15: Instruction memory arayüzü | E15: Komut çekme | F15: S | G15: Kritik | H15: Tamamlandı | I15: -
A16: T015 | B16: Faz 1 | C16: Tasarım | D16: Register file (x0=0, 2R/1W) | E16: Mimari register'lar | F16: S | G16: Kritik | H16: Tamamlandı | I16: T004
A17: T016 | B17: Faz 1 | C17: Tasarım | D17: Immediate generator (I/S/B/U/J) | E17: Immediate çıkarımı | F17: S | G17: Kritik | H17: Tamamlandı | I17: T004
A18: T017 | B18: Faz 1 | C18: Tasarım | D18: ALU (behavioral + ilk, ölç) | E18: Aritmetik/mantık; toplayıcıyı ölç-optimize | F18: M | G18: Kritik | H18: Tamamlandı | I18: - | J18: Önce +, gerekirse Kogge-Stone vs.
A19: T018 | B19: Faz 1 | C19: Tasarım | D19: ALU control | E19: funct → ALU op | F19: S | G19: Kritik | H19: Yapılacak | I19: T017
A20: T019 | B20: Faz 1 | C20: Tasarım | D20: Data memory arayüzü | E20: Load/store | F20: S | G20: Kritik | H20: Tamamlandı | I20: -
A21: T020 | B21: Faz 1 | C21: Tasarım | D21: Control/decode (kombinasyonel) | E21: opcode → kontrol sinyalleri | F21: M | G21: Kritik | H21: Yapılacak | I21: T004
A22: T021 | B22: Faz 1 | C22: Tasarım | D22: Datapath mux'lar + next-PC | E22: ALU src, WB src, PC seçimi | F22: S | G22: Kritik | H22: Yapılacak | I22: -
A23: T022 | B23: Faz 1 | C23: Tasarım | D23: M0 single-cycle RV32I bring-up | E23: İlk çalışan çekirdek | F23: M | G23: Kritik | H23: Yapılacak | I23: T013,T015,T017,T020 | J23: En basit ilk milestone
A24: T023 | B24: Faz 1 | C24: Tasarım | D24: csr.sv: 12-bit adres decode + izin | E24: CSR motoru iskeleti | F24: S | G24: Kritik | H24: Yapılacak | I24: T022 | J24: CSR temel çekirdeğin parçası
A25: T024 | B25: Faz 1 | C25: Tasarım | D25: CSR atomik oku/yaz/set/clear | E25: CSRRW/S/C + immediate | F25: M | G25: Kritik | H25: Yapılacak | I25: T023
A26: T025 | B26: Faz 1 | C26: Tasarım | D26: Temel CSR'lar (misa, mhartid, id'ler) | E26: Makine bilgisi; misa = uzantı ilanı | F26: S | G26: Kritik | H26: Yapılacak | I26: T023 | J26: IMACBFV bitlerini burada bildir
A27: T026 | B27: Faz 1 | C27: Tasarım | D27: Sayaç CSR'ları (mcycle/minstret +h) | E27: 64-bit sayaç iki register | F27: S | G27: Yüksek | H27: Yapılacak | I27: T023
A28: T027 | B28: Faz 1 | C28: Tasarım | D28: illegal-CSR sinyali | E28: Trap Faz 2'de tamamlanır | F28: S | G28: Yüksek | H28: Yapılacak | I28: T024 | J28: Bootstrapping
A29: T028 | B29: Faz 1 | C29: Tasarım | D29: CSR RAW hazard | E29: CSR yaz → oku bağımlılığı | F29: S | G29: Yüksek | H29: Yapılacak | I29: T024,T029
A30: T029 | B30: Faz 1 | C30: Tasarım | D30: Pipeline register'lar (4 adet) | E30: IF/ID … MEM/WB | F30: M | G30: Kritik | H30: Yapılacak | I30: T022 | J30: M2 5-stage
A31: T030 | B31: Faz 1 | C31: Tasarım | D31: Hazard detection unit | E31: Tehlike tespiti / stall | F31: M | G31: Kritik | H31: Yapılacak | I31: T029
A32: T031 | B32: Faz 1 | C32: Tasarım | D32: Forwarding/bypass unit | E32: Sonucu EX'e geri yönlendir | F32: M | G32: Kritik | H32: Yapılacak | I32: T029
A33: T032 | B33: Faz 1 | C33: Tasarım | D33: Stall/flush logic | E33: Bubble + branch flush | F33: M | G33: Kritik | H33: Yapılacak | I33: T029,T030
A34: T033 | B34: Faz 1 | C34: Tasarım | D34: Branch resolution + flush | E34: EX'te çöz, yanlışı temizle | F34: M | G34: Yüksek | H34: Yapılacak | I34: T029
A35: T034 | B35: Faz 1 | C35: Tasarım | D35: Basit branch predictor (ops.) | E35: Statik / BHT | F35: S | G35: Düşük | H35: Yapılacak | I35: T033 | J35: Opsiyonel v1
A36: T035 | B36: Faz 1 | C36: Doğrulama | D36: Directed asm testleri | E36: Elle basit programlar | F36: S | G36: Yüksek | H36: Yapılacak | I36: T022
A37: T036 | B37: Faz 1 | C37: Doğrulama | D37: riscv-arch-test (I + Zicsr) | E37: Uyumluluk | F37: M | G37: Kritik | H37: Yapılacak | I37: T022,T024
A38: T037 | B38: Faz 1 | C38: Doğrulama | D38: Spike co-sim (RV32I+Zicsr) | E38: Lockstep karşılaştırma | F38: M | G38: Kritik | H38: Yapılacak | I38: T009,T022
A39: T038 | B39: Faz 1 | C39: Doğrulama | D39: riscv-dv random | E39: Rastgele program | F39: M | G39: Yüksek | H39: Yapılacak | I39: T037
A40: T039 | B40: Faz 2 | C40: Tasarım | D40: Trap CSR'ları (mstatus/mtvec/…) | E40: Mevcut motora eklenir | F40: M | G40: Yüksek | H40: Yapılacak | I40: T024
...
